Workbook
Name Print_Area_MI: #REF!
Name 전: #REF!
Name 전: #REF!
Name 전: #REF!
Name 전: #REF!
Name 전: #REF!
Name 전: #REF!
Name 주택사업본부: #REF!
Name 주택사업본부: #REF!
Name 주택사업본부: #REF!
Name 주택사업본부: #REF!
Name 주택사업본부: #REF!
Name 주택사업본부: #REF!
Name 철구사업본부: #REF!
Name 철구사업본부: #REF!
Name 철구사업본부: #REF!
Name 철구사업본부: #REF!
Name 철구사업본부: #REF!
Name 철구사업본부: #REF!

Sheet 合并资产负债表
A1: 合并资产负债表
A2: 45838
A3: 编制单位：平阳县国诚控股有限公司 | H3: 单位：元 币种：人民币
A4: 项 目 | B4: 附注 | C4: 本年金额 | D4: 上年金额 | E4: 项 目 | F4: 附注 | G4: =C4 -> 本年金额 | H4: =D4 -> 上年金额
A5: 流动资产： | E5: 流动负债：
A6: 货币资金 | B6: 附注八、注释1 | C6: =IFERROR(VLOOKUP("*"&A6&"*",[4]资产负债表!$A$6:$C$59,3,0),0) -> 5.4792367e+09 | D6: =[6]合并资产负债表!C6 -> 2.0318434e+09 | E6: 短期借款 | F6: 附注八、注释18 | G6: =IFERROR(VLOOKUP("*"&E6&"*",[4]资产负债表!$F$6:$H$59,3,0),0) -> 5.4038893e+09 | H6: =[6]合并资产负债表!G6 -> 4.1507074e+09
A7: 交易性金融资产 | C7: =IFERROR(VLOOKUP("*"&A7&"*",[4]资产负债表!$A$6:$C$59,3,0),0) -> 0 | D7: =[6]合并资产负债表!C7 -> 0 | E7: 交易性金融负债 | G7: =IFERROR(VLOOKUP("*"&E7&"*",[4]资产负债表!$F$6:$H$59,3,0),0) -> 0 | H7: =[6]合并资产负债表!G7 -> 0
A8: 衍生金融资产 | C8: =IFERROR(VLOOKUP("*"&A8&"*",[4]资产负债表!$A$6:$C$59,3,0),0) -> 0 | D8: =[6]合并资产负债表!C8 -> 0 | E8: 衍生金融负债 | G8: =IFERROR(VLOOKUP("*"&E8&"*",[4]资产负债表!$F$6:$H$59,3,0),0) -> 0 | H8: =[6]合并资产负债表!G8 -> 0
A9: 应收票据 | C9: =IFERROR(VLOOKUP("*"&A9&"*",[4]资产负债表!$A$6:$C$59,3,0),0) -> 0 | D9: =[6]合并资产负债表!C9 -> 0 | E9: 应付票据 | F9: 附注八、注释19 | G9: =IFERROR(VLOOKUP("*"&E9&"*",[4]资产负债表!$F$6:$H$59,3,0),0) -> 344900000 | H9: =[6]合并资产负债表!G9 -> 73661438
A10: 应收账款 | B10: 附注八、注释2 | C10: =IFERROR(VLOOKUP("*"&A10&"*",[4]资产负债表!$A$6:$C$59,3,0),0) -> 1.751658e+09 | D10: =[6]合并资产负债表!C10 -> 1.7514714e+09 | E10: 应付账款 | F10: 附注八、注释20 | G10: =IFERROR(VLOOKUP("*"&E10&"*",[4]资产负债表!$F$6:$H$59,3,0),0) -> 5.1639652e+08 | H10: =[6]合并资产负债表!G10 -> 5.208724e+08
A11: 应收款项融资 | C11: =IFERROR(VLOOKUP("*"&A11&"*",[4]资产负债表!$A$6:$C$59,3,0),0) -> 0 | D11: =[6]合并资产负债表!C11 -> 0 | E11: 预收款项 | F11: 附注八、注释21 | G11: =IFERROR(VLOOKUP("*"&E11&"*",[4]资产负债表!$F$6:$H$59,3,0),0) -> 4982572.1 | H11: =[6]合并资产负债表!G11 -> 4966407.9
A12: 预付款项 | B12: 附注八、注释3 | C12: =IFERROR(VLOOKUP("*"&A12&"*",[4]资产负债表!$A$6:$C$59,3,0),0) -> 6.6989931e+08 | D12: =[6]合并资产负债表!C12 -> 6.2558075e+08 | E12: 合同负债 | F12: 附注八、注释22 | G12: =IFERROR(VLOOKUP("*"&E12&"*",[4]资产负债表!$F$6:$H$59,3,0),0) -> 3.7549781e+08 | H12: =[6]合并资产负债表!G12 -> 4.6627258e+08
A13: 其他应收款 | B13: 附注八、注释4 | C13: =IFERROR(VLOOKUP("*"&A13&"*",[4]资产负债表!$A$6:$C$59,3,0),0) -> 7.3075548e+09 | D13: =[6]合并资产负债表!C13 -> 7.3871053e+09 | E13: 应付职工薪酬 | F13: 附注八、注释23 | G13: =IFERROR(VLOOKUP("*"&E13&"*",[4]资产负债表!$F$6:$H$59,3,0),0) -> 8226436.6 | H13: =[6]合并资产负债表!G13 -> 13475144
A14: 其中：应收利息 | C14: =IFERROR(VLOOKUP("*"&A14&"*",[4]资产负债表!$A$6:$C$59,3,0),0) -> 0 | D14: =[6]合并资产负债表!C14 -> 0 | E14: 应交税费 | F14: 附注八、注释24 | G14: =IFERROR(VLOOKUP("*"&E14&"*",[4]资产负债表!$F$6:$H$59,3,0),0) -> 2.0608673e+08 | H14: =[6]合并资产负债表!G14 -> 2.3270842e+08
A15: 应收股利 | C15: =IFERROR(VLOOKUP("*"&A15&"*",[4]资产负债表!$A$6:$C$59,3,0),0) -> 0 | D15: =[6]合并资产负债表!C15 -> 0 | E15: 其他应付款 | F15: 附注八、注释25 | G15: =IFERROR(VLOOKUP("*"&E15&"*",[4]资产负债表!$F$6:$H$59,3,0),0) -> 1.1728644e+10 | H15: =[6]合并资产负债表!G15 -> 9.2471594e+09
A16: 存货 | B16: 附注八、注释5 | C16: =IFERROR(VLOOKUP("*"&A16&"*",[4]资产负债表!$A$6:$C$59,3,0),0) -> 7.355793e+10 | D16: =[6]合并资产负债表!C16 -> 6.928947e+10 | E16: 其中：应付利息 | G16: =IFERROR(VLOOKUP("*"&E16&"*",[4]资产负债表!$F$6:$H$59,3,0),0) -> 0 | H16: =[6]合并资产负债表!G16 -> 0
A17: 合同资产 | C17: =IFERROR(VLOOKUP("*"&A17&"*",[4]资产负债表!$A$6:$C$59,3,0),0) -> 0 | D17: =[6]合并资产负债表!C17 -> 0 | E17: 应付股利 | G17: =IFERROR(VLOOKUP("*"&E17&"*",[4]资产负债表!$F$6:$H$59,3,0),0) -> 0 | H17: =[6]合并资产负债表!G17 -> 0
A18: 持有待售资产 | C18: =IFERROR(VLOOKUP("*"&A18&"*",[4]资产负债表!$A$6:$C$59,3,0),0) -> 0 | D18: =[6]合并资产负债表!C18 -> 0 | E18: 持有待售负债 | G18: =IFERROR(VLOOKUP("*"&E18&"*",[4]资产负债表!$F$6:$H$59,3,0),0) -> 0 | H18: =[6]合并资产负债表!G18 -> 0
A19: 一年内到期的非流动资产 | C19: =IFERROR(VLOOKUP("*"&A19&"*",[4]资产负债表!$A$6:$C$59,3,0),0) -> 0 | D19: =[6]合并资产负债表!C19 -> 0 | E19: 一年内到期的非流动负债 | F19: 附注八、注释26 | G19: =IFERROR(VLOOKUP("*"&E19&"*",[4]资产负债表!$F$6:$H$59,3,0),0) -> 9.1183746e+09 | H19: =[6]合并资产负债表!G19 -> 7.0270944e+09
A20: 其他流动资产 | B20: 附注八、注释6 | C20: =IFERROR(VLOOKUP("*"&A20&"*",[4]资产负债表!$A$6:$C$59,3,0),0) -> 3.2781785e+08 | D20: =[6]合并资产负债表!C20 -> 2.925395e+08 | E20: 其他流动负债 | F20: 附注八、注释27 | G20: =IFERROR(VLOOKUP("*"&E20&"*",[4]资产负债表!$F$6:$H$59,3,0),0) -> 47431259 | H20: =[6]合并资产负债表!G20 -> 48812957
A21: 流动资产合计 | C21: =SUM(C6:C20)-C14-C15 -> 8.9094096e+10 | D21: =SUM(D6:D20)-D14-D15 -> 8.1378011e+10 | E21: 流动负债合计 | G21: =SUM(G6:G20)-G16-G17 -> 2.775443e+10 | H21: =SUM(H6:H20)-H16-H17 -> 2.1785731e+10
A22: 非流动资产： | E22: 非流动负债：
A23: 债权投资 | C23: =IFERROR(VLOOKUP("*"&A23&"*",[4]资产负债表!$A$6:$C$59,3,0),0) -> 0 | D23: =[6]合并资产负债表!C23 -> 0 | E23: 长期借款 | F23: 附注八、注释28 | G23: =IFERROR(VLOOKUP("*"&E23&"*",[4]资产负债表!$F$6:$H$59,3,0),0) -> 2.7273828e+10 | H23: =[6]合并资产负债表!G23 -> 2.5288171e+10
A24: 其他债权投资 | C24: =IFERROR(VLOOKUP("*"&A24&"*",[4]资产负债表!$A$6:$C$59,3,0),0) -> 0 | D24: =[6]合并资产负债表!C24 -> 0 | E24: 应付债券 | F24: 附注八、注释29 | G24: =IFERROR(VLOOKUP("*"&E24&"*",[4]资产负债表!$F$6:$H$59,3,0),0) -> 1.0170933e+10 | H24: =[6]合并资产负债表!G24 -> 1.2158848e+10 | J24: =C16-D16+C40-D40 -> 4.3001393e+09
A25: 长期应收款 | B25: 附注八、注释7 | C25: =IFERROR(VLOOKUP("*"&A25&"*",[4]资产负债表!$A$6:$C$59,3,0),0) -> 7.3584089e+08 | D25: =[6]合并资产负债表!C25 -> 7.2545054e+08 | E25: 其中：优先股 | G25: =IFERROR(VLOOKUP("*"&E25&"*",[4]资产负债表!$F$6:$H$59,3,0),0) -> 0 | H25: =[6]合并资产负债表!G25 -> 0
A26: 长期股权投资 | B26: 附注八、注释8 | C26: =IFERROR(VLOOKUP("*"&A26&"*",[4]资产负债表!$A$6:$C$59,3,0),0) -> 1.9023832e+08 | D26: =[6]合并资产负债表!C26 -> 1.9200878e+08 | E26: 永续债 | G26: =IFERROR(VLOOKUP("*"&E26&"*",[4]资产负债表!$F$6:$H$59,3,0),0) -> 0 | H26: =[6]合并资产负债表!G26 -> 0
A27: 其他权益工具投资 | B27: 附注八、注释9 | C27: =IFERROR(VLOOKUP("*"&A27&"*",[4]资产负债表!$A$6:$C$59,3,0),0) -> 2.7707634e+09 | D27: =[6]合并资产负债表!C27 -> 2.6630296e+09 | E27: 租赁负债 | F27: 附注八、注释30 | G27: =IFERROR(VLOOKUP("*"&E27&"*",[4]资产负债表!$F$6:$H$59,3,0),0) -> 6740599.3 | H27: =[6]合并资产负债表!G27 -> 6676196.3
A28: 其他非流动金融资产 | C28: =IFERROR(VLOOKUP("*"&A28&"*",[4]资产负债表!$A$6:$C$59,3,0),0) -> 0 | D28: =[6]合并资产负债表!C28 -> 0 | E28: 长期应付款 | F28: 附注八、注释31 | G28: =IFERROR(VLOOKUP("*"&E28&"*",[4]资产负债表!$F$6:$H$59,3,0),0) -> 9.1722603e+09 | H28: =[6]合并资产负债表!G28 -> 7.0486063e+09
A29: 投资性房地产 | B29: 附注八、注释10 | C29: =IFERROR(VLOOKUP("*"&A29&"*",[4]资产负债表!$A$6:$C$59,3,0),0) -> 1349698097 | D29: =[6]合并资产负债表!C29 -> 1345179539 | E29: 长期应付职工薪酬 | G29: =IFERROR(VLOOKUP("*"&E29&"*",[4]资产负债表!$F$6:$H$59,3,0),0) -> 0 | H29: =[6]合并资产负债表!G29 -> 0
A30: 固定资产 | B30: 附注八、注释11 | C30: =IFERROR(VLOOKUP("*"&A30&"*",[4]资产负债表!$A$6:$C$59,3,0),0) -> 2.1253805e+09 | D30: =[6]合并资产负债表!C30 -> 1226109865 | E30: 预计负债 | G30: =IFERROR(VLOOKUP("*"&E30&"*",[4]资产负债表!$F$6:$H$59,3,0),0) -> 0 | H30: =[6]合并资产负债表!G30 -> 0
A31: 在建工程 | B31: 附注八、注释12 | C31: =IFERROR(VLOOKUP("*"&A31&"*",[4]资产负债表!$A$6:$C$59,3,0),0) -> 1.6565164e+08 | D31: =[6]合并资产负债表!C31 -> 1.2903661e+08 | E31: 递延收益 | F31: 附注八、注释32 | G31: =IFERROR(VLOOKUP("*"&E31&"*",[4]资产负债表!$F$6:$H$59,3,0),0) -> 87182983 | H31: =[6]合并资产负债表!G31 -> 70329490
A32: 生产性生物资产 | C32: =IFERROR(VLOOKUP("*"&A32&"*",[4]资产负债表!$A$6:$C$59,3,0),0) -> 0 | D32: =[6]合并资产负债表!C32 -> 0 | E32: 递延所得税负债 | F32: 附注八、注释16 | G32: =IFERROR(VLOOKUP("*"&E32&"*",[4]资产负债表!$F$6:$H$59,3,0),0) -> 1.5246642e+08 | H32: =[6]合并资产负债表!G32 -> 1.5024752e+08
A33: 油气资产 | C33: =IFERROR(VLOOKUP("*"&A33&"*",[4]资产负债表!$A$6:$C$59,3,0),0) -> 0 | D33: =[6]合并资产负债表!C33 -> 0 | E33: 其他非流动负债 | G33: =IFERROR(VLOOKUP("*"&E33&"*",[4]资产负债表!$F$6:$H$59,3,0),0) -> 0 | H33: =[6]合并资产负债表!G33 -> 0
A34: 使用权资产 | B34: 附注八、注释13 | C34: =IFERROR(VLOOKUP("*"&A34&"*",[4]资产负债表!$A$6:$C$59,3,0),0) -> 8005093.7 | D34: =[6]合并资产负债表!C34 -> 9828455.4 | E34: 非流动负债合计 | G34: =SUM(G23:G33)-G25-G26 -> 4.6863411e+10 | H34: =SUM(H23:H33)-H25-H26 -> 4.4722879e+10
A35: 无形资产 | B35: 附注八、注释14 | C35: =IFERROR(VLOOKUP("*"&A35&"*",[4]资产负债表!$A$6:$C$59,3,0),0) -> 7.6408151e+09 | D35: =[6]合并资产负债表!C35 -> 8.5588895e+09 | E35: 负债合计 | G35: =G21+G34 -> 7.461784e+10 | H35: =H21+H34 -> 6.650861e+10
A36: 开发支出 | C36: =IFERROR(VLOOKUP("*"&A36&"*",[4]资产负债表!$A$6:$C$59,3,0),0) -> 0 | D36: =[6]合并资产负债表!C36 -> 0 | E36: 所有者权益：
A37: 商誉 | C37: =IFERROR(VLOOKUP("*"&A37&"*",[4]资产负债表!$A$6:$C$59,3,0),0) -> 0 | D37: =[6]合并资产负债表!C37 -> 0 | E37: 实收资本 | F37: 附注八、注释33 | G37: =IFERROR(VLOOKUP("*"&E37&"*",[4]资产负债表!$F$6:$H$59,3,0),0) -> 1500000000 | H37: =[6]合并资产负债表!G37 -> 1500000000
A38: 长期待摊费用 | B38: 附注八、注释15 | C38: =IFERROR(VLOOKUP("*"&A38&"*",[4]资产负债表!$A$6:$C$59,3,0),0) -> 93408629 | D38: =[6]合并资产负债表!C38 -> 1.0094377e+08 | E38: 其他权益工具 | G38: =IFERROR(VLOOKUP("*"&E38&"*",[4]资产负债表!$F$6:$H$59,3,0),0) -> 0 | H38: =[6]合并资产负债表!G38 -> 0
A39: 递延所得税资产 | B39: 附注八、注释16 | C39: =IFERROR(VLOOKUP("*"&A39&"*",[4]资产负债表!$A$6:$C$59,3,0),0) -> 23132518 | D39: =[6]合并资产负债表!C39 -> 21459416 | E39: 其中：优先股 | G39: =IFERROR(VLOOKUP("*"&E39&"*",[4]资产负债表!$F$6:$H$59,3,0),0) -> 0 | H39: =[6]合并资产负债表!G39 -> 0
A40: 其他非流动资产 | B40: 附注八、注释17 | C40: =IFERROR(VLOOKUP("*"&A40&"*",[4]资产负债表!$A$6:$C$59,3,0),0) -> 8.3068197e+08 | D40: =[6]合并资产负债表!C40 -> 7.9900194e+08 | E40: 永续债 | G40: =IFERROR(VLOOKUP("*"&E40&"*",[4]资产负债表!$F$6:$H$59,3,0),0) -> 0 | H40: =[6]合并资产负债表!G40 -> 0
...

Sheet 合并利润表 
A1: 合并利润表
A2: 2025年1-6月
A3: =合并资产负债表!A3 -> 编制单位：平阳县国诚控股有限公司 | D3: 单位：元 币种：人民币
A4: 项 目 | B4: 附注 | C4: 本年金额 | D4: 上年金额
A5: 一、营业总收入 | C5: =SUM(C6:C6) -> 3.8765794e+08 | D5: =SUM(D6:D6) -> 3.7040073e+08
A6: 其中：营业收入 | B6: 附注八、注释39 | C6: =IFERROR(VLOOKUP("*"&A6&"*",[4]利润表!$A$6:$C$71,3,0),0) -> 3.8765794e+08 | D6: ='[7]合并利润表 '!C6 -> 3.7040073e+08
A7: 二、营业总成本 | C7: =SUM(C8:C15)-C14-C15 -> 8.1494304e+08 | D7: =SUM(D8:D15)-D14-D15 -> 7.802419e+08
A8: 其中：营业成本 | B8: 附注八、注释39 | C8: =IFERROR(VLOOKUP("*"&A8&"*",[4]利润表!$A$6:$C$71,3,0),0) -> 4.1569707e+08 | D8: ='[7]合并利润表 '!C8 -> 3.9692361e+08
A9: 税金及附加 | C9: =IFERROR(VLOOKUP("*"&A9&"*",[4]利润表!$A$6:$C$71,3,0),0) -> 40381687 | D9: ='[7]合并利润表 '!C9 -> 18224409
A10: 销售费用 | C10: =IFERROR(VLOOKUP("*"&A10&"*",[4]利润表!$A$6:$C$71,3,0),0) -> 12251964 | D10: ='[7]合并利润表 '!C10 -> 6807576.7
A11: 管理费用 | C11: =IFERROR(VLOOKUP("*"&A11&"*",[4]利润表!$A$6:$C$71,3,0),0) -> 2.5359088e+08 | D11: ='[7]合并利润表 '!C11 -> 3.144442e+08
A12: 研发费用 | C12: =IFERROR(VLOOKUP("*"&A12&"*",[4]利润表!$A$6:$C$71,3,0),0) -> 0 | D12: ='[7]合并利润表 '!C12 -> 0
A13: 财务费用 | B13: 附注八、注释40 | C13: =IFERROR(VLOOKUP("*"&A13&"*",[4]利润表!$A$6:$C$71,3,0),0) -> 93021442 | D13: ='[7]合并利润表 '!C13 -> 43842097
A14: 其中:利息费用 | C14: =IFERROR(VLOOKUP("*"&A14&"*",[4]利润表!$A$6:$C$71,3,0),0) -> 0 | D14: ='[7]合并利润表 '!C14 -> 64759712
A15: 利息收入 | C15: =IFERROR(VLOOKUP("*"&A15&"*",[4]利润表!$A$6:$C$71,3,0),0) -> 0 | D15: ='[7]合并利润表 '!C15 -> 23214453
A16: 加：其他收益 | B16: 附注八、注释41 | C16: =IFERROR(VLOOKUP("*"&A16&"*",[4]利润表!$A$6:$C$71,3,0),0) -> 5944841.5 | D16: ='[7]合并利润表 '!C16 -> 4.0827469e+08
A17: 投资收益（损失以“-”号填列） | B17: 附注八、注释42 | C17: =IFERROR(VLOOKUP("*"&A17&"*",[4]利润表!$A$6:$C$71,3,0),0) -> -40800635 | D17: ='[7]合并利润表 '!C17 -> -2277170.5
A18: 其中：对联营企业和合营企业的投资收益 | C18: =IFERROR(VLOOKUP("*"&A18&"*",[4]利润表!$A$6:$C$71,3,0),0) -> 0 | D18: ='[7]合并利润表 '!C18 -> 0
A19: 以摊余成本计量的金融资产终止确认收益 | C19: =IFERROR(VLOOKUP("*"&A19&"*",[4]利润表!$A$6:$C$71,3,0),0) -> 0 | D19: ='[7]合并利润表 '!C19 -> 0
A20: 净敞口套期收益（损失以“-”号填列） | C20: =IFERROR(VLOOKUP("*"&A20&"*",[4]利润表!$A$6:$C$71,3,0),0) -> 0 | D20: ='[7]合并利润表 '!C20 -> 0
A21: 公允价值变动收益（损失以“-”号填列） | B21: 附注八、注释43 | C21: =IFERROR(VLOOKUP("*"&A21&"*",[4]利润表!$A$6:$C$71,3,0),0) -> 1561800 | D21: ='[7]合并利润表 '!C21 -> -1448948.8
A22: 信用减值损失（损失以“-”号填列） | B22: 附注八、注释44 | C22: =IFERROR(VLOOKUP("*"&A22&"*",[4]利润表!$A$6:$C$71,3,0),0) -> -7211088.6 | D22: ='[7]合并利润表 '!C22 -> -14003596
A23: 资产减值损失（损失以“-”号填列） | C23: =IFERROR(VLOOKUP("*"&A23&"*",[4]利润表!$A$6:$C$71,3,0),0) -> 0 | D23: ='[7]合并利润表 '!C23 -> 0
A24: 资产处置收益（损失以“-”号填列） | B24: 附注八、注释45 | C24: =IFERROR(VLOOKUP("*"&A24&"*",[4]利润表!$A$6:$C$71,3,0),0) -> 40950659 | D24: ='[7]合并利润表 '!C24 -> -25782661
A25: 三、营业利润（亏损以“-”号填列） | C25: =C5-C7+C16+C17+SUM(C20:C24) -> -4.2683952e+08 | D25: =D5-D7+D16+D17+SUM(D20:D24) -> -45078846
A26: 加：营业外收入 | B26: 附注八、注释46 | C26: =IFERROR(VLOOKUP("*"&A26&"*",[4]利润表!$A$6:$C$71,3,0),0) -> 5367322.7 | D26: ='[7]合并利润表 '!C26 -> 1589002
A27: 减：营业外支出 | B27: 附注八、注释47 | C27: =IFERROR(VLOOKUP("*"&A27&"*",[4]利润表!$A$6:$C$71,3,0),0) -> 26485334 | D27: ='[7]合并利润表 '!C27 -> 5894964.9
A28: 四、利润总额（亏损总额以“-”号填列） | C28: =C25+C26-C27 -> -4.4795754e+08 | D28: =D25+D26-D27 -> -49384809
A29: 减：所得税费用 | B29: 附注八、注释48 | C29: =IFERROR(VLOOKUP("*"&A29&"*",[4]利润表!$A$6:$C$71,3,0),0) -> 9803974.4 | D29: ='[7]合并利润表 '!C29 -> 195316.56
A30: 五、净利润（净亏损以“-”号填列） | C30: =C28-C29 -> -4.5776151e+08 | D30: =D28-D29 -> -49580125
A31: （一）按经营持续性分类 | C31: =C32+C33 -> -4.5776151e+08 | D31: =D32+D33 -> -49580125
A32: 1.持续经营净利润（净亏损以“-”号填列） | C32: =IFERROR(VLOOKUP("*"&A32&"*",[4]利润表!$A$6:$C$71,3,0),0) -> -4.5776151e+08 | D32: ='[7]合并利润表 '!C32 -> -49580125
A33: 2.终止经营净利润（净亏损以“-”号填列） | C33: =[1]利润表!C45 -> 0 | D33: 0
A34: （二）按所有权归属分类 | C34: =C35+C36 -> -4.5776151e+08 | D34: =D35+D36 -> -49580125
A35: 1.归属于母公司所有者的净利润（净亏损以“-”号填列） | C35: =IFERROR(VLOOKUP("*"&A35&"*",[4]利润表!$A$6:$C$71,3,0),0) -> -4.4175859e+08 | D35: ='[7]合并利润表 '!C35 -> -30312430
A36: 2.少数股东损益（净亏损以“-”号填列） | C36: =IFERROR(VLOOKUP("*"&A36&"*",[4]利润表!$A$6:$C$71,3,0),0) -> -16002919 | D36: ='[7]合并利润表 '!C36 -> -19267695
A37: 六、其他综合收益的税后净额 | C37: =C38+C53 -> 0 | D37: 0
A38: （一）归属于母公司所有者的其他综合收益的税后净额 | C38: =C39+C45 -> 0 | D38: 0
A39: 1. 不能重分类进损益的其他综合收益 | C39: =SUM(C40:C44) -> 0 | D39: 0
A40: （1）重新计量设定受益计划变动额
...

Sheet 合并现金流量表 
A1: 合并现金流量表
A2: 2025年1-6月
A3: =合并资产负债表!A3 -> 编制单位：平阳县国诚控股有限公司 | D3: 单位：元 币种：人民币
A4: 项 目 | B4: 附注 | C4: ='合并利润表 '!C4 -> 本年金额 | D4: ='合并利润表 '!D4 -> 上年金额
A5: 一、经营活动产生的现金流量
A6: 销售商品、提供劳务收到的现金 | C6: =IFERROR(VLOOKUP("*"&A6&"*",[4]现金流量表!$A$6:$D$63,3,0),0) -> 4.1959187e+08 | D6: ='[7]合并现金流量表 '!C6 -> 7.5448765e+08
A7: 收到的税费返还 | C7: =IFERROR(VLOOKUP("*"&A7&"*",[4]现金流量表!$A$6:$D$63,3,0),0) -> 15559.84 | D7: ='[7]合并现金流量表 '!C7 -> 30930.9
A8: 收到其他与经营活动有关的现金 | C8: =IFERROR(VLOOKUP("*"&A8&"*",[4]现金流量表!$A$6:$D$63,3,0),0) -> 1.0645109e+10 | D8: ='[7]合并现金流量表 '!C8 -> 6.4527277e+09
A9: 经营活动现金流入小计 | C9: =SUM(C6:C8) -> 1.1064716e+10 | D9: =SUM(D6:D8) -> 7.2072463e+09
A10: 购买商品、接受劳务支付的现金 | C10: =IFERROR(VLOOKUP("*"&A10&"*",[4]现金流量表!$A$6:$D$63,3,0),0) -> 4.6728902e+09 | D10: ='[7]合并现金流量表 '!C10 -> 4.2359202e+09
A11: 支付给职工以及为职工支付的现金 | C11: =IFERROR(VLOOKUP("*"&A11&"*",[4]现金流量表!$A$6:$D$63,3,0),0) -> 1.4804018e+08 | D11: ='[7]合并现金流量表 '!C11 -> 51065422
A12: 支付的各项税费 | C12: =IFERROR(VLOOKUP("*"&A12&"*",[4]现金流量表!$A$6:$D$63,3,0),0) -> 1.0849919e+08 | D12: ='[7]合并现金流量表 '!C12 -> 60006707
A13: 支付其他与经营活动有关的现金 | C13: =IFERROR(VLOOKUP("*"&A13&"*",[4]现金流量表!$A$6:$D$63,3,0),0) -> 7.206381e+09 | D13: ='[7]合并现金流量表 '!C13 -> 4.7431438e+09
A14: 经营活动现金流出小计 | C14: =SUM(C10:C13) -> 1.2135811e+10 | D14: =SUM(D10:D13) -> 9.0901362e+09
A15: 经营活动产生的现金流量净额 | C15: =C9-C14 -> -1.0710943e+09 | D15: =D9-D14 -> -1.8828899e+09
A16: 二、投资活动产生的现金流量
A17: 收回投资收到的现金 | C17: =IFERROR(VLOOKUP("*"&A17&"*",[4]现金流量表!$A$6:$D$63,3,0),0) -> 5336250 | D17: ='[7]合并现金流量表 '!C17 -> 127710000
A18: 取得投资收益收到的现金 | C18: =IFERROR(VLOOKUP("*"&A18&"*",[4]现金流量表!$A$6:$D$63,3,0),0) -> 3.5120478e+08 | D18: ='[7]合并现金流量表 '!C18 -> 2306694.1
A19: 处置固定资产、无形资产和其他长期资产收回的现金净额 | C19: =IFERROR(VLOOKUP("*"&A19&"*",[4]现金流量表!$A$6:$D$63,3,0),0) -> 2.0272445e+08 | D19: ='[7]合并现金流量表 '!C19 -> 2071671.2
A20: 处置子公司及其他营业单位收到的现金净额 | C20: =IFERROR(VLOOKUP("*"&A20&"*",[4]现金流量表!$A$6:$D$63,3,0),0) -> 0 | D20: ='[7]合并现金流量表 '!C20 -> 300000000
A21: 收到其他与投资活动有关的现金 | C21: =IFERROR(VLOOKUP("*"&A21&"*",[4]现金流量表!$A$6:$D$63,3,0),0) -> 2409687.9 | D21: ='[7]合并现金流量表 '!C21 -> 0
A22: 投资活动现金流入小计 | C22: =SUM(C17:C21) -> 5.6167517e+08 | D22: =SUM(D17:D21) -> 4.3208837e+08
A23: 购建固定资产、无形资产和其他长期资产支付的现金 | C23: =IFERROR(VLOOKUP("*"&A23&"*",[4]现金流量表!$A$6:$D$63,3,0),0) -> 5.8009629e+08 | D23: ='[7]合并现金流量表 '!C23 -> 1.2237113e+09
A24: 投资支付的现金 | C24: =IFERROR(VLOOKUP("*"&A24&"*",[4]现金流量表!$A$6:$D$63,3,0),0) -> 114050000 | D24: ='[7]合并现金流量表 '!C24 -> 61219933
A25: 取得子公司及其他营业单位支付的现金净额 | C25: =IFERROR(VLOOKUP("*"&A25&"*",[4]现金流量表!$A$6:$D$63,3,0),0) -> 113070000 | D25: ='[7]合并现金流量表 '!C25 -> 3500000
A26: 支付其他与投资活动有关的现金 | C26: =IFERROR(VLOOKUP("*"&A26&"*",[4]现金流量表!$A$6:$D$63,3,0),0) -> 0 | D26: ='[7]合并现金流量表 '!C26 -> 0
A27: 投资活动现金流出小计 | C27: =SUM(C23:C26) -> 8.0721629e+08 | D27: =SUM(D23:D26) -> 1.2884312e+09
A28: 投资活动产生的现金流量净额 | C28: =C22-C27 -> -2.4554112e+08 | D28: =D22-D27 -> -8.5634283e+08
A29: 三、筹资活动产生的现金流量
A30: 吸收投资收到的现金 | C30: =IFERROR(VLOOKUP("*"&A30&"*",[4]现金流量表!$A$6:$D$63,3,0),0) -> 366670000 | D30: ='[7]合并现金流量表 '!C30 -> 6504200
A31: 其中：子公司吸收少数股东投资收到的现金 | C31: =IFERROR(VLOOKUP("*"&A31&"*",[4]现金流量表!$A$6:$D$63,3,0),0) -> 0 | D31: ='[7]合并现金流量表 '!C31 -> 0
A32: 取得借款收到的现金 | C32: =IFERROR(VLOOKUP("*"&A32&"*",[4]现金流量表!$A$6:$D$63,3,0),0) -> 1.1991332e+10 | D32: ='[7]合并现金流量表 '!C32 -> 7.3436162e+09
A33: 收到其他与筹资活动有关的现金 | C33: =IFERROR(VLOOKUP("*"&A33&"*",[4]现金流量表!$A$6:$D$63,3,0),0) -> 2.1427567e+09 | D33: ='[7]合并现金流量表 '!C33 -> 2369755779
A34: 筹资活动现金流入小计 | C34: =SUM(C30+C32+C33) -> 1.4500759e+10 | D34: =SUM(D30+D32+D33) -> 9.7198762e+09
A35: 偿还债务支付的现金 | C35: =IFERROR(VLOOKUP("*"&A35&"*",[4]现金流量表!$A$6:$D$63,3,0),0) -> 8.1239684e+09 | D35: ='[7]合并现金流量表 '!C35 -> 4.6126132e+09
A36: 分配股利、利润或偿付利息支付的现金 | C36: =IFERROR(VLOOKUP("*"&A36&"*",[4]现金流量表!$A$6:$D$63,3,0),0) -> 8.8172423e+08 | D36: ='[7]合并现金流量表 '!C36 -> 9.2066079e+08
A37: 其中：子公司支付给少数股东的股利、利润 | C37: =IFERROR(VLOOKUP("*"&A37&"*",[4]现金流量表!$A$6:$D$63,3,0),0) -> 0 | D37: ='[7]合并现金流量表 '!C37 -> 0
A38: 支付其他与筹资活动有关的现金 | C38: =IFERROR(VLOOKUP("*"&A38&"*",[4]现金流量表!$A$6:$D$63,3,0),0) -> 7.2852499e+08 | D38: ='[7]合并现金流量表 '!C38 -> 1.294304e+09
A39: 筹资活动现金流出小计 | C39: =C35+C36+C38 -> 9.7342176e+09 | D39: =D35+D36+D38 -> 6.8275779e+09
A40: 筹资活动产生的现金流量净额 | C40: =C34-C39 -> 4.7665409e+09 | D40: =D34-D39 -> 2.8922983e+09
...

Sheet 合并所有者权益变动表 
A1: 合并所有者权益变动表
A2: ='合并利润表 '!A2 -> 2025年1-6月
A3: =合并资产负债表!A3 -> 编制单位：平阳县国诚控股有限公司 | N3: 单位：元 币种：人民币
A4: 项 目 | B4: 本年金额
B5: 归属于母公司所有者权益 | M5: 少数股东权益 | N5: 所有者权益合计
B6: 实收资本 | C6: 其他权益工具 | F6: 资本公积 | G6: 减：库存股 | H6: 其他综合收益 | I6: 专项储备 | J6: 盈余公积 | K6: 未分配利润 | L6: 小计
C7: 优先股 | D7: 永续债 | E7: 其他
A8: 一、上年年末余额 | B8: ='[6]合并所有者权益变动表 '!B36 -> 1500000000 | C8: ='[6]合并所有者权益变动表 '!C36 -> 0 | D8: ='[6]合并所有者权益变动表 '!D36 -> 0 | E8: ='[6]合并所有者权益变动表 '!E36 -> 0 | F8: ='[6]合并所有者权益变动表 '!F36 -> 2.1059068e+10 | G8: ='[6]合并所有者权益变动表 '!G36 -> 0 | H8: ='[6]合并所有者权益变动表 '!H36 -> 3.9096213e+08 | I8: ='[6]合并所有者权益变动表 '!I36 -> 6141337.5 | ... K8: ='[6]合并所有者权益变动表 '!K36 -> 2.5399285e+09 | L8: =合并资产负债表!$H$47 -> 2.5566433e+10 | M8: =合并资产负债表!$H$48 -> 5.073906e+09 | N8: =合并资产负债表!$H$49 -> 3.0640339e+10 | P8: =(#REF!-'合并利润表 '!#REF!)/(N8+(N17*7/12)+(#REF!/2)+(#REF!/2)) -> #REF! | R8: =M8-合并资产负债表!H48 -> 0
A9: 加：会计政策变更 | L9: =SUM(B9:F9)-G9+SUM(H9:K9) -> 0 | N9: =L9+M9 -> 0
A10: 前期差错更正 | L10: =SUM(B10:F10)-G10+SUM(H10:K10) -> 0 | N10: =L10+M10 -> 0
A11: 同一控制下企业合并 | L11: =SUM(B11:F11)-G11+SUM(H11:K11) -> 0 | N11: =L11+M11 -> 0
A12: 其他 | L12: =SUM(B12:F12)-G12+SUM(H12:K12) -> 0 | N12: =L12+M12 -> 0
A13: 二、本年年初余额 | B13: =SUM(B8:B12) -> 1500000000 | C13: =SUM(C8:C12) -> 0 | D13: =SUM(D8:D12) -> 0 | E13: =SUM(E8:E12) -> 0 | F13: =SUM(F8:F12) -> 2.1059068e+10 | G13: =SUM(G8:G12) -> 0 | H13: =SUM(H8:H12) -> 3.9096213e+08 | I13: =SUM(I8:I12) -> 6141337.5 | ... N13: =SUM(N8:N12) -> 3.0640339e+10
A14: 三、本年增减变动金额(减少以“-”号填列) | B14: =B15+B16+B21+B25+B32+B35 -> 0 | C14: =C15+C16+C21+C25+C32+C35 -> 0 | D14: =D15+D16+D21+D25+D32+D35 -> 0 | E14: =E15+E16+E21+E25+E32+E35 -> 0 | F14: =F15+F16+F21+F25+F32+F35 -> -2.5377612e+08 | G14: =G15+G16+G21+G25+G32+G35 -> 0 | H14: =H15+H16+H21+H25+H32+H35 -> 0 | I14: =I15+I16+I21+I25+I32+I35 -> -3939484.1 | ... K14: =K15+K16+K21+K25+K32+K35 -> -4.4223542e+08 | L14: =SUM(B14:F14)-G14+SUM(H14:K14) -> -6.9995102e+08 | M14: =M15+M16+M21+M25+M32+M35 -> 4.6948379e+08 | N14: =L14+M14 -> -2.3046723e+08
A15: （一）综合收益总额 | K15: ='合并利润表 '!C35 -> -4.4175859e+08 | L15: =SUM(B15:F15)-G15+SUM(H15:K15) -> -4.4175859e+08 | M15: ='合并利润表 '!C36 -> -16002919 | N15: =L15+M15 -> -4.5776151e+08
A16: （二）所有者投入和减少资本 | B16: =B17+B18+B19+B20 -> 0 | C16: =C17+C18+C19+C20 -> 0 | D16: =D17+D18+D19+D20 -> 0 | E16: =E17+E18+E19+E20 -> 0 | F16: =F17+F18+F19+F20 -> -2.5377612e+08 | G16: =G17+G18+G19+G20 -> 0 | H16: =H17+H18+H19+H20 -> 0 | I16: =I17+I18+I19+I20 -> 0 | ... K16: =K17+K18+K19+K20 -> 0 | L16: =SUM(B16:F16)-G16+SUM(H16:K16) -> -2.5377612e+08 | M16: =M17+M18+M19+M20 -> 4.8548671e+08 | N16: =L16+M16 -> 2.3171059e+08
A17: 1. 所有者投入的普通股 | L17: =SUM(B17:F17)-G17+SUM(H17:K17) -> 0 | M17: =[1]所有者权益变动表!$M$18 -> 0 | N17: =L17+M17 -> 0
A18: 2．其他权益工具持有者投入资本 | L18: =SUM(B18:F18)-G18+SUM(H18:K18) -> 0 | N18: =L18+M18 -> 0
A19: 3．股份支付计入所有者权益的金额 | L19: =SUM(B19:F19)-G19+SUM(H19:K19) -> 0 | N19: =L19+M19 -> 0
A20: 4．其他 | F20: =合并资产负债表!G41-合并资产负债表!H41 -> -2.5377612e+08 | H20: =合并资产负债表!G43-合并资产负债表!H43 -> 0 | L20: =SUM(B20:F20)-G20+SUM(H20:K20) -> -2.5377612e+08 | M20: =合并资产负债表!G48-合并资产负债表!H48-'合并所有者权益变动表 '!M15 -> 4.8548671e+08 | N20: =L20+M20 -> 2.3171059e+08
A21: （三）利润分配 | B21: =B22+B23+B24 -> 0 | C21: =C22+C23+C24 -> 0 | D21: =D22+D23+D24 -> 0 | E21: =E22+E23+E24 -> 0 | F21: =F22+F23+F24 -> 0 | G21: =G22+G23+G24 -> 0 | H21: =H22+H23+H24 -> 0 | I21: =I22+I23+I24 -> 0 | ... K21: =K22+K23+K24 -> -476827.32 | L21: =SUM(B21:F21)-G21+SUM(H21:K21) -> -476827.32 | M21: =M22+M23+M24 -> 0 | N21: =L21+M21 -> -476827.32
A22: 1．提取盈余公积 | J22: =[1]所有者权益变动表!$J$23 -> 0 | K22: =0-J22 -> 0 | L22: =SUM(B22:F22)-G22+SUM(H22:K22) -> 0 | N22: =L22+M22 -> 0
A23: 2．对所有者的分配 | K23: =-[4]TB表!$AF$267 -> -476827.32 | L23: =SUM(B23:F23)-G23+SUM(H23:K23) -> -476827.32 | N23: =L23+M23 -> -476827.32
A24: 3．其他 | K24: =[1]所有者权益变动表!$L$26 -> 0 | L24: =SUM(B24:F24)-G24+SUM(H24:K24) -> 0 | N24: =L24+M24 -> 0
A25: （四）所有者权益内部结转 | B25: =SUM(B26:B31) -> 0 | C25: =SUM(C26:C31) -> 0 | D25: =SUM(D26:D31) -> 0 | E25: =SUM(E26:E31) -> 0 | F25: =SUM(F26:F31) -> 0 | G25: =SUM(G26:G31) -> 0 | H25: =SUM(H26:H31) -> 0 | I25: =SUM(I26:I31) -> 0 | ... K25: =SUM(K26:K31) -> 0 | L25: =SUM(B25:F25)-G25+SUM(H25:K25) -> 0 | M25: =SUM(M26:M31) -> 0 | N25: =L25+M25 -> 0
A26: 1．资本公积转增资本 | L26: =SUM(B26:F26)-G26+SUM(H26:K26) -> 0 | N26: =L26+M26 -> 0
A27: 2．盈余公积转增资本 | L27: =SUM(B27:F27)-G27+SUM(H27:K27) -> 0 | N27: =L27+M27 -> 0
A28: 3．盈余公积弥补亏损 | L28: =SUM(B28:F28)-G28+SUM(H28:K28) -> 0 | N28: =L28+M28 -> 0
A29: 4．设定受益计划变动额结转留存收益 | L29: =SUM(B29:F29)-G29+SUM(H29:K29) -> 0 | N29: =L29+M29 -> 0
A30: 5. 其他综合收益结转留存收益 | L30: =SUM(B30:F30)-G30+SUM(H30:K30) -> 0 | N30: =L30+M30 -> 0
A31: 6. 其他 | L31: =SUM(B31:F31)-G31+SUM(H31:K31) -> 0 | N31: =L31+M31 -> 0
A32: （五）专项储备 | B32: =B33-B34 -> 0 | C32: =C33-C34 -> 0 | D32: =D33-D34 -> 0 | E32: =E33-E34 -> 0 | F32: =F33-F34 -> 0 | G32: =G33-G34 -> 0 | H32: =H33-H34 -> 0 | I32: =I33-I34 -> -3939484.1 | ... K32: =K33-K34 -> 0 | L32: =SUM(B32:F32)-G32+SUM(H32:K32) -> -3939484.1 | M32: =M33-M34 -> 0 | N32: =L32+M32 -> -3939484.1
A33: 1．本年提取 | I33: =合并资产负债表!G44-合并资产负债表!H44 -> -3939484.1 | L33: =SUM(B33:F33)-G33+SUM(H33:K33) -> -3939484.1 | N33: =L33+M33 -> -3939484.1
A34: 2．本年使用 | L34: =SUM(B34:F34)-G34+SUM(H34:K34) -> 0 | N34: =L34+M34 -> 0
A35: （六）其他 | L35: =SUM(B35:F35)-G35+SUM(H35:K35) -> 0 | N35: =L35+M35 -> 0
A36: 四、本年年末余额 | B36: =B13+B14 -> 1500000000 | C36: =C13+C14 -> 0 | D36: =D13+D14 -> 0 | E36: =E13+E14 -> 0 | F36: =F13+F14 -> 2.0805292e+10 | G36: =G13+G14 -> 0 | H36: =H13+H14 -> 3.9096213e+08 | I36: =I13+I14 -> 2201853.4 | ... N36: =N13+N14 -> 3.0409872e+10
A37: 法定代表人： | G37: 主管会计工作负责人： | M37: 会计机构负责人：
A38: 合并所有者权益变动表
A39: =A2 -> 2025年1-6月
A40: =A3 -> 编制单位：平阳县国诚控股有限公司 | N40: 单位：元 币种：人民币
...

Sheet 资产负债表
A1: 资产负债表
A2: =合并资产负债表!A2 -> 45838
A3: =合并资产负债表!A3 -> 编制单位：平阳县国诚控股有限公司 | H3: 单位：元 币种：人民币
A4: 资 产 | B4: 附注 | C4: =合并资产负债表!C4 -> 本年金额 | D4: =合并资产负债表!D4 -> 上年金额 | E4: 负债和所有者权益 | F4: 附注 | G4: =合并资产负债表!G4 -> 本年金额 | H4: =合并资产负债表!H4 -> 上年金额
A5: 流动资产： | E5: 流动负债：
A6: 货币资金 | C6: =IFERROR(VLOOKUP("*"&A6&"*",[5]资产负债表!$A$7:$C$48,3,0),0) -> 3.5199075e+08 | D6: =[6]资产负债表!C6 -> 2090973 | E6: 短期借款 | G6: =IFERROR(VLOOKUP("*"&E6&"*",[5]资产负债表!$F$6:$H$47,3,0),0) -> 1.0015124e+09 | H6: =[6]资产负债表!G6 -> 300412500
A7: 交易性金融资产 | C7: =IFERROR(VLOOKUP("*"&A7&"*",[5]资产负债表!$A$7:$C$48,3,0),0) -> 0 | D7: =[6]资产负债表!C7 -> 0 | E7: 交易性金融负债 | G7: =IFERROR(VLOOKUP("*"&E7&"*",[5]资产负债表!$F$6:$H$47,3,0),0) -> 0 | H7: =[6]资产负债表!G7 -> 0
A8: 衍生金融资产 | C8: =IFERROR(VLOOKUP("*"&A8&"*",[5]资产负债表!$A$7:$C$48,3,0),0) -> 0 | D8: =[6]资产负债表!C8 -> 0 | E8: 衍生金融负债 | G8: =IFERROR(VLOOKUP("*"&E8&"*",[5]资产负债表!$F$6:$H$47,3,0),0) -> 0 | H8: =[6]资产负债表!G8 -> 0
A9: 应收票据 | C9: =IFERROR(VLOOKUP("*"&A9&"*",[5]资产负债表!$A$7:$C$48,3,0),0) -> 0 | D9: =[6]资产负债表!C9 -> 0 | E9: 应付票据 | G9: =IFERROR(VLOOKUP("*"&E9&"*",[5]资产负债表!$F$6:$H$47,3,0),0) -> 0 | H9: =[6]资产负债表!G9 -> 0
A10: 应收账款 | C10: =IFERROR(VLOOKUP("*"&A10&"*",[5]资产负债表!$A$7:$C$48,3,0),0) -> 0 | D10: =[6]资产负债表!C10 -> 0 | E10: 应付账款 | G10: =IFERROR(VLOOKUP("*"&E10&"*",[5]资产负债表!$F$6:$H$47,3,0),0) -> 0 | H10: =[6]资产负债表!G10 -> 0
A11: 应收款项融资 | C11: =IFERROR(VLOOKUP("*"&A11&"*",[5]资产负债表!$A$7:$C$48,3,0),0) -> 0 | D11: =[6]资产负债表!C11 -> 0 | E11: 预收款项 | G11: =IFERROR(VLOOKUP("*"&E11&"*",[5]资产负债表!$F$6:$H$47,3,0),0) -> 0 | H11: =[6]资产负债表!G11 -> 0
A12: 预付款项 | C12: =IFERROR(VLOOKUP("*"&A12&"*",[5]资产负债表!$A$7:$C$48,3,0),0) -> 0 | D12: =[6]资产负债表!C12 -> 0 | E12: 合同负债 | G12: =IFERROR(VLOOKUP("*"&E12&"*",[5]资产负债表!$F$6:$H$47,3,0),0) -> 0 | H12: =[6]资产负债表!G12 -> 0
A13: 其他应收款 | B13: 附注十二、注释1 | C13: =IFERROR(VLOOKUP("*"&A13&"*",[5]资产负债表!$A$7:$C$48,3,0),0) -> 6.2535705e+09 | D13: =[6]资产负债表!C13 -> 4.5504273e+09 | E13: 应付职工薪酬 | G13: =IFERROR(VLOOKUP("*"&E13&"*",[5]资产负债表!$F$6:$H$47,3,0),0) -> 0 | H13: =[6]资产负债表!G13 -> 0
A14: 其中：应收利息 | C14: =IFERROR(VLOOKUP("*"&A14&"*",[5]资产负债表!$A$7:$C$48,3,0),0) -> 0 | D14: =[6]资产负债表!C14 -> 0 | E14: 应交税费 | G14: =IFERROR(VLOOKUP("*"&E14&"*",[5]资产负债表!$F$6:$H$47,3,0),0) -> 0 | H14: =[6]资产负债表!G14 -> 0
A15: 应收股利 | C15: =IFERROR(VLOOKUP("*"&A15&"*",[5]资产负债表!$A$7:$C$48,3,0),0) -> 0 | D15: =[6]资产负债表!C15 -> 0 | E15: 其他应付款 | G15: =IFERROR(VLOOKUP("*"&E15&"*",[5]资产负债表!$F$6:$H$47,3,0),0) -> 73000000 | H15: =[6]资产负债表!G15 -> 43000000
A16: 存货 | C16: =IFERROR(VLOOKUP("*"&A16&"*",[5]资产负债表!$A$7:$C$48,3,0),0) -> 78053739 | D16: =[6]资产负债表!C16 -> 0 | E16: 其中：应付利息 | G16: =IFERROR(VLOOKUP("*"&E16&"*",[5]资产负债表!$F$6:$H$47,3,0),0) -> 0 | H16: =[6]资产负债表!G16 -> 0
A17: 合同资产 | C17: =IFERROR(VLOOKUP("*"&A17&"*",[5]资产负债表!$A$7:$C$48,3,0),0) -> 0 | D17: =[6]资产负债表!C17 -> 0 | E17: 应付股利 | G17: =IFERROR(VLOOKUP("*"&E17&"*",[5]资产负债表!$F$6:$H$47,3,0),0) -> 0 | H17: =[6]资产负债表!G17 -> 0
A18: 持有待售资产 | C18: =IFERROR(VLOOKUP("*"&A18&"*",[5]资产负债表!$A$7:$C$48,3,0),0) -> 0 | D18: =[6]资产负债表!C18 -> 0 | E18: 持有待售负债 | G18: =IFERROR(VLOOKUP("*"&E18&"*",[5]资产负债表!$F$6:$H$47,3,0),0) -> 0 | H18: =[6]资产负债表!G18 -> 0
A19: 一年内到期的非流动资产 | C19: =IFERROR(VLOOKUP("*"&A19&"*",[5]资产负债表!$A$7:$C$48,3,0),0) -> 0 | D19: =[6]资产负债表!C19 -> 0 | E19: 一年内到期的非流动负债 | G19: =IFERROR(VLOOKUP("*"&E19&"*",[5]资产负债表!$F$6:$H$47,3,0),0) -> 7515217.6 | H19: =[6]资产负债表!G19 -> 1.5661507e+08
A20: 其他流动资产 | C20: =IFERROR(VLOOKUP("*"&A20&"*",[5]资产负债表!$A$7:$C$48,3,0),0) -> 0 | D20: =[6]资产负债表!C20 -> 0 | E20: 其他流动负债 | G20: =IFERROR(VLOOKUP("*"&E20&"*",[5]资产负债表!$F$6:$H$47,3,0),0) -> 0 | H20: =[6]资产负债表!G20 -> 0
A21: 流动资产合计 | C21: =SUM(C6:C20)-C14-C15 -> 6.683615e+09 | D21: =SUM(D6:D20)-D14-D15 -> 4.5525183e+09 | E21: 流动负债合计 | G21: =SUM(G6:G20)-G16-G17 -> 1.0820276e+09 | H21: =SUM(H6:H20)-H16-H17 -> 5.0002757e+08
A22: 非流动资产： | E22: 非流动负债：
A23: 债权投资 | C23: =IFERROR(VLOOKUP("*"&A23&"*",[5]资产负债表!$A$7:$C$48,3,0),0) -> 0 | D23: =[6]资产负债表!C23 -> 0 | E23: 长期借款 | G23: =IFERROR(VLOOKUP("*"&E23&"*",[5]资产负债表!$F$6:$H$47,3,0),0) -> 884100000 | H23: =[6]资产负债表!G23 -> 292500000
A24: 其他债权投资 | C24: =IFERROR(VLOOKUP("*"&A24&"*",[5]资产负债表!$A$7:$C$48,3,0),0) -> 0 | D24: =[6]资产负债表!C24 -> 0 | E24: 应付债券 | G24: =IFERROR(VLOOKUP("*"&E24&"*",[5]资产负债表!$F$6:$H$47,3,0),0) -> 4745585250 | H24: =[6]资产负债表!G24 -> 3773382750
A25: 长期应收款 | C25: =IFERROR(VLOOKUP("*"&A25&"*",[5]资产负债表!$A$7:$C$48,3,0),0) -> 3511000 | D25: =[6]资产负债表!C25 -> 3000000 | E25: 其中：优先股 | G25: =IFERROR(VLOOKUP("*"&E25&"*",[5]资产负债表!$F$6:$H$47,3,0),0) -> 0 | H25: =[6]资产负债表!G25 -> 0
A26: 长期股权投资 | B26: 附注十二、注释2 | C26: =IFERROR(VLOOKUP("*"&A26&"*",[5]资产负债表!$A$7:$C$48,3,0),0) -> 2.3722029e+10 | D26: =[6]资产负债表!C26 -> 2.3722029e+10 | E26: 永续债 | G26: =IFERROR(VLOOKUP("*"&E26&"*",[5]资产负债表!$F$6:$H$47,3,0),0) -> 0 | H26: =[6]资产负债表!G26 -> 0
A27: 其他权益工具投资 | C27: =IFERROR(VLOOKUP("*"&A27&"*",[5]资产负债表!$A$7:$C$48,3,0),0) -> 0 | D27: =[6]资产负债表!C27 -> 0 | E27: 租赁负债 | G27: =IFERROR(VLOOKUP("*"&E27&"*",[5]资产负债表!$F$6:$H$47,3,0),0) -> 0 | H27: =[6]资产负债表!G27 -> 0
A28: 其他非流动金融资产 | C28: =IFERROR(VLOOKUP("*"&A28&"*",[5]资产负债表!$A$7:$C$48,3,0),0) -> 0 | D28: =[6]资产负债表!C28 -> 0 | E28: 长期应付款 | G28: =IFERROR(VLOOKUP("*"&E28&"*",[5]资产负债表!$F$6:$H$47,3,0),0) -> 0 | H28: =[6]资产负债表!G28 -> 0
A29: 投资性房地产 | C29: =IFERROR(VLOOKUP("*"&A29&"*",[5]资产负债表!$A$7:$C$48,3,0),0) -> 0 | D29: =[6]资产负债表!C29 -> 0 | E29: 长期应付职工薪酬 | G29: =IFERROR(VLOOKUP("*"&E29&"*",[5]资产负债表!$F$6:$H$47,3,0),0) -> 0 | H29: =[6]资产负债表!G29 -> 0
A30: 固定资产 | C30: =IFERROR(VLOOKUP("*"&A30&"*",[5]资产负债表!$A$7:$C$48,3,0),0) -> 0 | D30: =[6]资产负债表!C30 -> 0 | E30: 预计负债 | G30: =IFERROR(VLOOKUP("*"&E30&"*",[5]资产负债表!$F$6:$H$47,3,0),0) -> 0 | H30: =[6]资产负债表!G30 -> 0
A31: 在建工程 | C31: =IFERROR(VLOOKUP("*"&A31&"*",[5]资产负债表!$A$7:$C$48,3,0),0) -> 0 | D31: =[6]资产负债表!C31 -> 0 | E31: 递延收益 | G31: =IFERROR(VLOOKUP("*"&E31&"*",[5]资产负债表!$F$6:$H$47,3,0),0) -> 0 | H31: =[6]资产负债表!G31 -> 0
A32: 生产性生物资产 | C32: =IFERROR(VLOOKUP("*"&A32&"*",[5]资产负债表!$A$7:$C$48,3,0),0) -> 0 | D32: =[6]资产负债表!C32 -> 0 | E32: 递延所得税负债 | G32: =IFERROR(VLOOKUP("*"&E32&"*",[5]资产负债表!$F$6:$H$47,3,0),0) -> 0 | H32: =[6]资产负债表!G32 -> 0
A33: 油气资产 | C33: =IFERROR(VLOOKUP("*"&A33&"*",[5]资产负债表!$A$7:$C$48,3,0),0) -> 0 | D33: =[6]资产负债表!C33 -> 0 | E33: 其他非流动负债 | G33: =IFERROR(VLOOKUP("*"&E33&"*",[5]资产负债表!$F$6:$H$47,3,0),0) -> 0 | H33: =[6]资产负债表!G33 -> 0
A34: 使用权资产 | C34: =IFERROR(VLOOKUP("*"&A34&"*",[5]资产负债表!$A$7:$C$48,3,0),0) -> 0 | D34: =[6]资产负债表!C34 -> 0 | E34: 非流动负债合计 | G34: =SUM(G23:G33)-G25-G26 -> 5629685250 | H34: =SUM(H23:H33)-H25-H26 -> 4065882750
A35: 无形资产 | C35: =IFERROR(VLOOKUP("*"&A35&"*",[5]资产负债表!$A$7:$C$48,3,0),0) -> 0 | D35: =[6]资产负债表!C35 -> 0 | E35: 负债合计 | G35: =G21+G34 -> 6.7117129e+09 | H35: =H21+H34 -> 4.5659103e+09
A36: 开发支出 | C36: =IFERROR(VLOOKUP("*"&A36&"*",[5]资产负债表!$A$7:$C$48,3,0),0) -> 0 | D36: =[6]资产负债表!C36 -> 0 | E36: 所有者权益：
A37: 商誉 | C37: =IFERROR(VLOOKUP("*"&A37&"*",[5]资产负债表!$A$7:$C$48,3,0),0) -> 0 | D37: =[6]资产负债表!C37 -> 0 | E37: 实收资本 | G37: =IFERROR(VLOOKUP("*"&E37&"*",[5]资产负债表!$F$6:$H$47,3,0),0) -> 1500000000 | H37: =[6]资产负债表!G37 -> 1500000000
A38: 长期待摊费用 | C38: =IFERROR(VLOOKUP("*"&A38&"*",[5]资产负债表!$A$7:$C$48,3,0),0) -> 0 | D38: =[6]资产负债表!C38 -> 0 | E38: 其他权益工具 | G38: =IFERROR(VLOOKUP("*"&E38&"*",[5]资产负债表!$F$6:$H$47,3,0),0) -> 0 | H38: =[6]资产负债表!G38 -> 0
A39: 递延所得税资产 | C39: =IFERROR(VLOOKUP("*"&A39&"*",[5]资产负债表!$A$7:$C$48,3,0),0) -> 12500 | D39: =[6]资产负债表!C39 -> 12500 | E39: 其中：优先股 | G39: =IFERROR(VLOOKUP("*"&E39&"*",[5]资产负债表!$F$6:$H$47,3,0),0) -> 0 | H39: =[6]资产负债表!G39 -> 0
A40: 其他非流动资产 | C40: =IFERROR(VLOOKUP("*"&A40&"*",[5]资产负债表!$A$7:$C$48,3,0),0) -> 0 | D40: =[6]资产负债表!C40 -> 0 | E40: 永续债 | G40: =IFERROR(VLOOKUP("*"&E40&"*",[5]资产负债表!$F$6:$H$47,3,0),0) -> 0 | H40: =[6]资产负债表!G40 -> 0
...

Sheet 利润表
A1: 利润表
A2: ='合并利润表 '!A2:D2 -> 2025年1-6月
A3: =合并资产负债表!A3 -> 编制单位：平阳县国诚控股有限公司 | D3: 单位：元 币种：人民币
A4: 项 目 | B4: 附注 | C4: ='合并利润表 '!C4 -> 本年金额 | D4: ='合并利润表 '!D4 -> 上年金额
A5: 一、营业收入 | C5: =IFERROR(VLOOKUP("*"&A5&"*",[5]利润表!$A$6:$D$51,3,0),0) -> 0 | D5: =[7]利润表!C5 -> 0
A6: 减：营业成本 | C6: =IFERROR(VLOOKUP("*"&A6&"*",[5]利润表!$A$6:$D$51,3,0),0) -> 0 | D6: =[7]利润表!C6 -> 0
A7: 税金及附加 | C7: =IFERROR(VLOOKUP("*"&A7&"*",[5]利润表!$A$6:$D$51,3,0),0) -> 0 | D7: =[7]利润表!C7 -> 0
A8: 销售费用 | C8: =IFERROR(VLOOKUP("*"&A8&"*",[5]利润表!$A$6:$D$51,3,0),0) -> 0 | D8: =[7]利润表!C8 -> 0
A9: 管理费用 | C9: =IFERROR(VLOOKUP("*"&A9&"*",[5]利润表!$A$6:$D$51,3,0),0) -> 1303200 | D9: =[7]利润表!C9 -> 150000
A10: 研发费用 | C10: =IFERROR(VLOOKUP("*"&A10&"*",[5]利润表!$A$6:$D$51,3,0),0) -> 0 | D10: =[7]利润表!C10 -> 0
A11: 财务费用 | C11: =IFERROR(VLOOKUP("*"&A11&"*",[5]利润表!$A$6:$D$51,3,0),0) -> 12891673 | D11: =[7]利润表!C11 -> 3318061.3
A12: 其中：利息费用 | C12: =IFERROR(VLOOKUP("*"&A12&"*",[5]利润表!$A$6:$D$51,3,0),0) -> 0 | D12: =[7]利润表!C12 -> 0
A13: 利息收入 | C13: =IFERROR(VLOOKUP("*"&A13&"*",[5]利润表!$A$6:$D$51,3,0),0) -> 0 | D13: =[7]利润表!C13 -> 0
A14: 加：其他收益 | C14: =IFERROR(VLOOKUP("*"&A14&"*",[5]利润表!$A$6:$D$51,3,0),0) -> 0 | D14: =[7]利润表!C14 -> 0
A15: 投资收益（损失以“-”号填列） | C15: =IFERROR(VLOOKUP("*"&A15&"*",[5]利润表!$A$6:$D$51,3,0),0) -> 0 | D15: =[7]利润表!C15 -> 0
A16: 其中：对联营企业和合营企业的投资收益 | C16: =IFERROR(VLOOKUP("*"&A16&"*",[5]利润表!$A$6:$D$51,3,0),0) -> 0 | D16: =[7]利润表!C16 -> 0
... A22: 资产处置收益（损失以“-”号填列） | C22: =IFERROR(VLOOKUP("*"&A22&"*",[5]利润表!$A$6:$D$51,3,0),0) -> 0 | D22: =[7]利润表!C22 -> 0
A23: 二、营业利润（亏损以“-”号填列） | C23: =C5-SUM(C6:C11)+SUM(C14:C22)-C16-C17 -> -14194873 | D23: =D5-SUM(D6:D11)+SUM(D14:D22)-D16-D17 -> -3468061.3
A24: 加：营业外收入 | C24: =IFERROR(VLOOKUP("*"&A24&"*",[5]利润表!$A$6:$D$51,3,0),0) -> 0.01 | D24: =[7]利润表!C24 -> 0
A25: 减：营业外支出 | C25: =IFERROR(VLOOKUP("*"&A25&"*",[5]利润表!$A$6:$D$51,3,0),0) -> 0 | D25: =[7]利润表!C25 -> 0
A26: 三、利润总额（亏损总额以“-”号填列） | C26: =C23+C24-C25 -> -14194873 | D26: =D23+D24-D25 -> -3468061.3
A27: 减：所得税费用 | C27: =IFERROR(VLOOKUP("*"&A27&"*",[5]利润表!$A$6:$D$51,3,0),0) -> 0 | D27: =[7]利润表!C27 -> 0
A28: 四、净利润（净亏损以“-”号填列） | C28: =C26-C27 -> -14194873 | D28: =D26-D27 -> -3468061.3
A29: （一）持续经营净利润（净亏损以“-”号填列） | C29: =IFERROR(VLOOKUP("*"&A29&"*",[5]利润表!$A$6:$D$51,3,0),0) -> -14194873 | D29: =[7]利润表!C29 -> -3468061.3
A30: （二）终止经营净利润（净亏损以“-”号填列）
A31: 五、其他综合收益的税后净额 | C31: =C32+C38 -> 0 | D31: =D32+D38 -> 0
A32: （一）不能重分类进损益的其他综合收益 | C32: =SUM(C33:C37) -> 0 | D32: =SUM(D33:D37) -> 0
A33: 1.重新计量设定受益计划变动额
A34: 2.权益法下不能转损益的其他综合收益
A35: 3.其他权益工具投资公允价值变动
A36: 4.企业自身信用风险公允价值变动
A37: 5.其他
A38: （二）将重分类进损益的其他综合收益 | C38: =SUM(C39:C45) -> 0 | D38: =SUM(D39:D45) -> 0
A39: 1.权益法下可转损益的其他综合收益
A40: 2.其他债权投资公允价值变动
A41: 3.金融资产重分类计入其他综合收益的金额
A42: 4.其他债权投资信用减值准备
A43: 5.现金流量套期储备
A44: 6.外币财务报表折算差额
A45: 7.其他
...

Sheet 现金流量表
A1: 现金流量表
A2: =利润表!A2 -> 2025年1-6月
A3: =合并资产负债表!A3 -> 编制单位：平阳县国诚控股有限公司 | D3: 单位：元 币种：人民币
A4: 项 目 | B4: 附注 | C4: ='合并现金流量表 '!C4 -> 本年金额 | D4: ='合并现金流量表 '!D4 -> 上年金额
A5: 一、经营活动产生的现金流量
A6: 销售商品、提供劳务收到的现金 | C6: =IFERROR(VLOOKUP("*"&A6&"*",[5]现金流量表!$A$6:$D$65,3,0),0) -> 0 | D6: =[7]现金流量表!C6 -> 0
A7: 收到的税费返还 | C7: =IFERROR(VLOOKUP("*"&A7&"*",[5]现金流量表!$A$6:$D$65,3,0),0) -> 0 | D7: =[7]现金流量表!C7 -> 0
A8: 收到其他与经营活动有关的现金 | C8: =IFERROR(VLOOKUP("*"&A8&"*",[5]现金流量表!$A$6:$D$65,3,0),0) -> 30146558 | D8: =[7]现金流量表!C8 -> 30002515
A9: 经营活动现金流入小计 | C9: =SUM(C6:C8) -> 30146558 | D9: =SUM(D6:D8) -> 30002515
A10: 购买商品、接受劳务支付的现金 | C10: =IFERROR(VLOOKUP("*"&A10&"*",[5]现金流量表!$A$6:$D$65,3,0),0) -> 78053739 | D10: =[7]现金流量表!C10 -> 0
A11: 支付给职工以及为职工支付的现金 | C11: =IFERROR(VLOOKUP("*"&A11&"*",[5]现金流量表!$A$6:$D$65,3,0),0) -> 0 | D11: =[7]现金流量表!C11 -> 0
A12: 支付的各项税费 | C12: =IFERROR(VLOOKUP("*"&A12&"*",[5]现金流量表!$A$6:$D$65,3,0),0) -> 0 | D12: =[7]现金流量表!C12 -> 0
A13: 支付其他与经营活动有关的现金 | C13: =IFERROR(VLOOKUP("*"&A13&"*",[5]现金流量表!$A$6:$D$65,3,0),0) -> 1.6239512e+09 | D13: =[7]现金流量表!C13 -> 1.1279387e+09
A14: 经营活动现金流出小计 | C14: =SUM(C10:C13) -> 1.7020049e+09 | D14: =SUM(D10:D13) -> 1.1279387e+09
A15: 经营活动产生的现金流量净额 | C15: =C9-C14 -> -1.6718584e+09 | D15: =D9-D14 -> -1.0979362e+09
A16: 二、投资活动产生的现金流量
A17: 收回投资收到的现金 | C17: =IFERROR(VLOOKUP("*"&A17&"*",[5]现金流量表!$A$6:$D$65,3,0),0) -> 0 | D17: =[7]现金流量表!C17 -> 0
A18: 取得投资收益收到的现金 | C18: =IFERROR(VLOOKUP("*"&A18&"*",[5]现金流量表!$A$6:$D$65,3,0),0) -> 0 | D18: =[7]现金流量表!C18 -> 0
A19: 处置固定资产、无形资产和其他长期资产收回的现金净额 | C19: =IFERROR(VLOOKUP("*"&A19&"*",[5]现金流量表!$A$6:$D$65,3,0),0) -> 0 | D19: =[7]现金流量表!C19 -> 0
A20: 处置子公司及其他营业单位收到的现金净额 | C20: =IFERROR(VLOOKUP("*"&A20&"*",[5]现金流量表!$A$6:$D$65,3,0),0) -> 0 | D20: =[7]现金流量表!C20 -> 0
A21: 收到其他与投资活动有关的现金 | C21: =IFERROR(VLOOKUP("*"&A21&"*",[5]现金流量表!$A$6:$D$65,3,0),0) -> 0 | D21: =[7]现金流量表!C21 -> 0
A22: 投资活动现金流入小计 | C22: =C17+C18+C19+C20+C21 -> 0 | D22: =D17+D18+D19+D20+D21 -> 0
A23: 购建固定资产、无形资产和其他长期资产支付的现金 | C23: =IFERROR(VLOOKUP("*"&A23&"*",[5]现金流量表!$A$6:$D$65,3,0),0) -> 0 | D23: =[7]现金流量表!C23 -> 0
A24: 投资支付的现金 | C24: =IFERROR(VLOOKUP("*"&A24&"*",[5]现金流量表!$A$6:$D$65,3,0),0) -> 0 | D24: =[7]现金流量表!C24 -> 0
A25: 取得子公司及其他营业单位支付的现金净额 | C25: =IFERROR(VLOOKUP("*"&A25&"*",[5]现金流量表!$A$6:$D$65,3,0),0) -> 0 | D25: =[7]现金流量表!C25 -> 0
A26: 支付其他与投资活动有关的现金 | C26: =IFERROR(VLOOKUP("*"&A26&"*",[5]现金流量表!$A$6:$D$65,3,0),0) -> 0 | D26: =[7]现金流量表!C26 -> 0
A27: 投资活动现金流出小计 | C27: =C23+C24+C25+C26 -> 0 | D27: =D23+D24+D25+D26 -> 0
A28: 投资活动产生的现金流量净额 | C28: =C22-C27 -> 0 | D28: =D22-D27 -> 0
A29: 三、筹资活动产生的现金流量
A30: 吸收投资收到的现金 | C30: =IFERROR(VLOOKUP("*"&A30&"*",[5]现金流量表!$A$6:$D$65,3,0),0) -> 0 | D30: =[7]现金流量表!C30 -> 0
A31: 取得借款收到的现金 | C31: =IFERROR(VLOOKUP("*"&A31&"*",[5]现金流量表!$A$6:$D$65,3,0),0) -> 2271100000 | D31: =[7]现金流量表!C31 -> 300000000
A32: 收到其他与筹资活动有关的现金 | C32: =IFERROR(VLOOKUP("*"&A32&"*",[5]现金流量表!$A$6:$D$65,3,0),0) -> 0 | D32: =[7]现金流量表!C32 -> 1000000000
A33: 筹资活动现金流入小计 | C33: =SUM(C30:C32) -> 2271100000 | D33: =SUM(D30:D32) -> 1300000000
A34: 偿还债务支付的现金 | C34: =IFERROR(VLOOKUP("*"&A34&"*",[5]现金流量表!$A$6:$D$65,3,0),0) -> 1.5529746e+08 | D34: =[7]现金流量表!C34 -> 1.8940658e+08
A35: 分配股利、利润或偿付利息支付的现金 | C35: =IFERROR(VLOOKUP("*"&A35&"*",[5]现金流量表!$A$6:$D$65,3,0),0) -> 94044377 | D35: =[7]现金流量表!C35 -> 9535767.4
A36: 支付其他与筹资活动有关的现金 | C36: =IFERROR(VLOOKUP("*"&A36&"*",[5]现金流量表!$A$6:$D$65,3,0),0) -> 0 | D36: =[7]现金流量表!C36 -> 0
A37: 筹资活动现金流出小计 | C37: =SUM(C34:C36) -> 2.4934184e+08 | D37: =SUM(D34:D36) -> 1.9894234e+08
A38: 筹资活动产生的现金流量净额 | C38: =C33-C37 -> 2.0217582e+09 | D38: =D33-D37 -> 1.1010577e+09
A39: 四、汇率变动对现金及现金等价物的影响
A40: 五、现金及现金等价物净增加额 | C40: =C15+C28+C38+C39 -> 3.4989977e+08 | D40: =D15+D28+D38+D39 -> 3121504.5
...

Sheet 所有者权益变动表
A1: 所有者权益变动表
A2: =现金流量表!A2 -> 2025年1-6月
A3: =合并资产负债表!A3 -> 编制单位：平阳县国诚控股有限公司 | L3: 单位：元 币种：人民币
A4: 项目 | B4: 本年金额
B5: 实收资本 | C5: 其他权益工具 | F5: 资本公积 | G5: 减：库存股 | H5: 其他综合收益 | I5: 专项储备 | J5: 盈余公积 | K5: 未分配利润 | L5: 所有者权益合计
A6: 项目 | C6: 优先股 | D6: 永续债 | E6: 其他
A7: 一、上年年末余额 | B7: =[6]所有者权益变动表!B34 -> 1500000000 | C7: =[6]所有者权益变动表!C34 -> 0 | D7: =[6]所有者权益变动表!D34 -> 0 | E7: =[6]所有者权益变动表!E34 -> 0 | F7: =[6]所有者权益变动表!F34 -> 2.2232029e+10 | G7: =[6]所有者权益变动表!G34 -> 0 | H7: =[6]所有者权益变动表!H34 -> 0 | I7: =[6]所有者权益变动表!I34 -> 0 | ... K7: =[6]所有者权益变动表!K34 -> -20379531 | L7: =SUM(B7:K7) -> 2.371165e+10
A8: 加： 会计政策变更 | L8: =SUM(B8:F8)-G8+SUM(H8:K8) -> 0
A9: 前期差错更正 | L9: =SUM(B9:F9)-G9+SUM(H9:K9) -> 0
A10: 其他 | L10: =SUM(B10:F10)-G10+SUM(H10:K10) -> 0
A11: 二、本年年初余额 | B11: =SUM(B7:B10) -> 1500000000 | C11: =SUM(C7:C10) -> 0 | D11: =SUM(D7:D10) -> 0 | E11: =SUM(E7:E10) -> 0 | F11: =SUM(F7:F10) -> 2.2232029e+10 | G11: =SUM(G7:G10) -> 0 | H11: =SUM(H7:H10) -> 0 | I11: =SUM(I7:I10) -> 0 | ... K11: =SUM(K7:K10) -> -20379531 | L11: =SUM(B11:F11)-G11+SUM(H11:K11) -> 2.371165e+10
A12: 三、本年增减变动金额(减少以“-”号填列) | B12: =B13+B14+B19+B23+B30+B33 -> 0 | C12: =C13+C14+C19+C23+C30+C33 -> 0 | D12: =D13+D14+D19+D23+D30+D33 -> 0 | E12: =E13+E14+E19+E23+E30+E33 -> 0 | F12: =F13+F14+F19+F23+F30+F33 -> 0 | G12: =G13+G14+G19+G23+G30+G33 -> 0 | H12: =H13+H14+H19+H23+H30+H33 -> 0 | I12: =I13+I14+I19+I23+I30+I33 -> 0 | ... K12: =K13+K14+K19+K23+K30+K33 -> -14194873 | L12: =SUM(B12:F12)-G12+SUM(H12:K12) -> -14194873
A13: （一）综合收益总额 | H13: =利润表!C31 -> 0 | K13: =利润表!C28 -> -14194873 | L13: =SUM(B13:F13)-G13+SUM(H13:K13) -> -14194873
A14: （二）所有者投入和减少资本 | B14: =SUM(B15:B18) -> 0 | C14: =SUM(C15:C18) -> 0 | D14: =SUM(D15:D18) -> 0 | E14: =SUM(E15:E18) -> 0 | F14: =SUM(F15:F18) -> 0 | G14: =SUM(G15:G18) -> 0 | H14: =SUM(H15:H18) -> 0 | I14: =SUM(I15:I18) -> 0 | ... K14: =SUM(K15:K18) -> 0 | L14: =SUM(B14:F14)-G14+SUM(H14:K14) -> 0
A15: 1. 所有者投入的普通股 | L15: =SUM(B15:F15)-G15+SUM(H15:K15) -> 0
A16: 2．其他权益工具持有者投入资本 | L16: =SUM(B16:F16)-G16+SUM(H16:K16) -> 0
A17: 3．股份支付计入所有者权益的金额 | L17: =SUM(B17:F17)-G17+SUM(H17:K17) -> 0
A18: 4．其他 | F18: =资产负债表!G41-资产负债表!H41 -> 0 | H18: =资产负债表!G43-资产负债表!H43 -> 0 | L18: =SUM(B18:F18)-G18+SUM(H18:K18) -> 0
A19: （三）利润分配 | B19: =SUM(B20:B22) -> 0 | C19: =SUM(C20:C22) -> 0 | D19: =SUM(D20:D22) -> 0 | E19: =SUM(E20:E22) -> 0 | F19: =SUM(F20:F22) -> 0 | G19: =SUM(G20:G22) -> 0 | H19: =SUM(H20:H22) -> 0 | I19: =SUM(I20:I22) -> 0 | ... K19: =SUM(K20:K22) -> 0 | L19: =SUM(B19:F19)-G19+SUM(H19:K19) -> 0
A20: 1．提取盈余公积 | J20: =[3]所有者权益变动表!$J$21 -> 0 | K20: =0-J20 -> 0 | L20: =SUM(B20:F20)-G20+SUM(H20:K20) -> 0
A21: 2．对所有者的分配 | L21: =SUM(B21:F21)-G21+SUM(H21:K21) -> 0
A22: 3．其他 | L22: =SUM(B22:F22)-G22+SUM(H22:K22) -> 0
A23: （四）所有者权益内部结转 | B23: =SUM(B24:B29) -> 0 | C23: =SUM(C24:C29) -> 0 | D23: =SUM(D24:D29) -> 0 | E23: =SUM(E24:E29) -> 0 | F23: =SUM(F24:F29) -> 0 | G23: =SUM(G24:G29) -> 0 | H23: =SUM(H24:H29) -> 0 | I23: =SUM(I24:I29) -> 0 | ... K23: =SUM(K24:K29) -> 0 | L23: =SUM(B23:F23)-G23+SUM(H23:K23) -> 0
A24: 1．资本公积转增资本 | L24: =SUM(B24:F24)-G24+SUM(H24:K24) -> 0
A25: 2．盈余公积转增资本 | L25: =SUM(B25:F25)-G25+SUM(H25:K25) -> 0
A26: 3．盈余公积弥补亏损 | L26: =SUM(B26:F26)-G26+SUM(H26:K26) -> 0
A27: 4．设定受益计划变动额结转留存收益 | L27: =SUM(B27:F27)-G27+SUM(H27:K27) -> 0
A28: 5.其他综合收益结转留存收益 | L28: =SUM(B28:F28)-G28+SUM(H28:K28) -> 0
A29: 6. 其他 | L29: =SUM(B29:F29)-G29+SUM(H29:K29) -> 0
A30: （五）专项储备 | B30: =B31-B32 -> 0 | C30: =C31-C32 -> 0 | D30: =D31-D32 -> 0 | E30: =E31-E32 -> 0 | F30: =F31-F32 -> 0 | G30: =G31-G32 -> 0 | H30: =H31-H32 -> 0 | I30: =I31-I32 -> 0 | ... K30: =K31-K32 -> 0 | L30: =SUM(B30:F30)-G30+SUM(H30:K30) -> 0
A31: 1．本年提取 | L31: =SUM(B31:F31)-G31+SUM(H31:K31) -> 0
A32: 2．本年使用 | L32: =SUM(B32:F32)-G32+SUM(H32:K32) -> 0
A33: （六）其他 | L33: =SUM(B33:F33)-G33+SUM(H33:K33) -> 0
A34: 四、本年年末余额 | B34: =B11+B12 -> 1500000000 | C34: =C11+C12 -> 0 | D34: =D11+D12 -> 0 | E34: =E11+E12 -> 0 | F34: =F11+F12 -> 2.2232029e+10 | G34: =G11+G12 -> 0 | H34: =H11+H12 -> 0 | I34: =I11+I12 -> 0 | ... K34: =K11+K12 -> -34574404 | L34: =SUM(B34:F34)-G34+SUM(H34:K34) -> 2.3697455e+10
A35: 法定代表人： | E35: 主管会计工作负责人： | K35: 会计机构负责人：
A36: 所有者权益变动表
A37: =A2 -> 2025年1-6月
A38: =A3 -> 编制单位：平阳县国诚控股有限公司 | L38: 单位：元 币种：人民币
A39: 项目 | B39: 上年金额
B40: 实收资本 | C40: 其他权益工具 | F40: 资本公积 | G40: 减：库存股 | H40: 其他综合收益 | I40: 专项储备 | J40: 盈余公积 | K40: 未分配利润 | L40: 所有者权益合计
...
